2024-06-25 22:12:34,043 INFO    StreamThr :1292 [internal.py:wandb_internal():85] W&B internal server running at pid: 1292, started at: 2024-06-25 22:12:34.043720
2024-06-25 22:12:34,043 DEBUG   HandlerThread:1292 [handler.py:handle_request():158] handle_request: status
2024-06-25 22:12:34,063 INFO    WriterThread:1292 [datastore.py:open_for_write():87] open: C:\Users\Bobby\Akash_Django\R\Droupout2 (another copy)\PFLlib\system\wandb\run-20240625_221234-qk87n3cy\run-qk87n3cy.wandb
2024-06-25 22:12:34,063 DEBUG   SenderThread:1292 [sender.py:send():378] send: header
2024-06-25 22:12:34,107 DEBUG   SenderThread:1292 [sender.py:send():378] send: run
2024-06-25 22:12:34,942 ERROR   SenderThread:1292 [internal_api.py:execute():344] 404 response executing GraphQL.
2024-06-25 22:12:34,942 ERROR   SenderThread:1292 [internal_api.py:execute():345] {"errors":[{"message":"entity NaveenSomiReddy not found during upsertBucket","path":["upsertBucket"]}],"data":{"upsertBucket":null}}
2024-06-25 22:12:34,942 ERROR   SenderThread:1292 [sender.py:send_run():970] It appears that you do not have permission to access the requested resource. Please reach out to the project owner to grant you access. If you have the correct permissions, verify that there are no issues with your networking setup.(Error 404: Not Found)
Traceback (most recent call last):
  File "C:\Users\Bobby\AppData\Local\Programs\Python\Python312\Lib\site-packages\wandb\sdk\lib\retry.py", line 131, in __call__
    result = self._call_fn(*args, **kwargs)
             ^^^^^^^^^^^^^^^^^^^^^^^^^^^^^^
  File "C:\Users\Bobby\AppData\Local\Programs\Python\Python312\Lib\site-packages\wandb\sdk\internal\internal_api.py", line 340, in execute
    return self.client.execute(*args, **kwargs)  # type: ignore
           ^^^^^^^^^^^^^^^^^^^^^^^^^^^^^^^^^^^^
  File "C:\Users\Bobby\AppData\Local\Programs\Python\Python312\Lib\site-packages\wandb\vendor\gql-0.2.0\wandb_gql\client.py", line 52, in execute
    result = self._get_result(document, *args, **kwargs)
             ^^^^^^^^^^^^^^^^^^^^^^^^^^^^^^^^^^^^^^^^^^^
  File "C:\Users\Bobby\AppData\Local\Programs\Python\Python312\Lib\site-packages\wandb\vendor\gql-0.2.0\wandb_gql\client.py", line 60, in _get_result
    return self.transport.execute(document, *args, **kwargs)
           ^^^^^^^^^^^^^^^^^^^^^^^^^^^^^^^^^^^^^^^^^^^^^^^^^
  File "C:\Users\Bobby\AppData\Local\Programs\Python\Python312\Lib\site-packages\wandb\sdk\lib\gql_request.py", line 59, in execute
    request.raise_for_status()
  File "C:\Users\Bobby\AppData\Local\Programs\Python\Python312\Lib\site-packages\requests\models.py", line 1024, in raise_for_status
    raise HTTPError(http_error_msg, response=self)
requests.exceptions.HTTPError: 404 Client Error: Not Found for url: https://api.wandb.ai/graphql

During handling of the above exception, another exception occurred:

Traceback (most recent call last):
  File "C:\Users\Bobby\AppData\Local\Programs\Python\Python312\Lib\site-packages\wandb\sdk\internal\sender.py", line 968, in send_run
    server_run = self._init_run(run, config_value_dict)
                 ^^^^^^^^^^^^^^^^^^^^^^^^^^^^^^^^^^^^^^
  File "C:\Users\Bobby\AppData\Local\Programs\Python\Python312\Lib\site-packages\wandb\sdk\internal\sender.py", line 1013, in _init_run
    server_run, inserted, server_messages = self._api.upsert_run(
                                            ^^^^^^^^^^^^^^^^^^^^^
  File "C:\Users\Bobby\AppData\Local\Programs\Python\Python312\Lib\site-packages\wandb\apis\normalize.py", line 73, in wrapper
    raise err
  File "C:\Users\Bobby\AppData\Local\Programs\Python\Python312\Lib\site-packages\wandb\apis\normalize.py", line 41, in wrapper
    return func(*args, **kwargs)
           ^^^^^^^^^^^^^^^^^^^^^
  File "C:\Users\Bobby\AppData\Local\Programs\Python\Python312\Lib\site-packages\wandb\sdk\internal\internal_api.py", line 2188, in upsert_run
    response = self.gql(
               ^^^^^^^^^
  File "C:\Users\Bobby\AppData\Local\Programs\Python\Python312\Lib\site-packages\wandb\sdk\internal\internal_api.py", line 312, in gql
    ret = self._retry_gql(
          ^^^^^^^^^^^^^^^^
  File "C:\Users\Bobby\AppData\Local\Programs\Python\Python312\Lib\site-packages\wandb\sdk\lib\retry.py", line 147, in __call__
    retry_timedelta_triggered = check_retry_fn(e)
                                ^^^^^^^^^^^^^^^^^
  File "C:\Users\Bobby\AppData\Local\Programs\Python\Python312\Lib\site-packages\wandb\util.py", line 965, in check_retry_fn
    return fallback_retry_fn(e)
           ^^^^^^^^^^^^^^^^^^^^
  File "C:\Users\Bobby\AppData\Local\Programs\Python\Python312\Lib\site-packages\wandb\util.py", line 907, in no_retry_auth
    raise CommError(
wandb.errors.CommError: It appears that you do not have permission to access the requested resource. Please reach out to the project owner to grant you access. If you have the correct permissions, verify that there are no issues with your networking setup.(Error 404: Not Found)
2024-06-25 22:12:35,584 DEBUG   HandlerThread:1292 [handler.py:handle_request():158] handle_request: shutdown
2024-06-25 22:12:35,589 INFO    HandlerThread:1292 [handler.py:finish():882] shutting down handler
2024-06-25 22:12:35,957 INFO    SenderThread:1292 [sender.py:finish():1545] shutting down sender
2024-06-25 22:12:36,130 INFO    WriterThread:1292 [datastore.py:close():296] close: C:\Users\Bobby\Akash_Django\R\Droupout2 (another copy)\PFLlib\system\wandb\run-20240625_221234-qk87n3cy\run-qk87n3cy.wandb
