2024-06-25 22:02:41,190 INFO    StreamThr :24736 [internal.py:wandb_internal():85] W&B internal server running at pid: 24736, started at: 2024-06-25 22:02:41.182086
2024-06-25 22:02:41,190 DEBUG   HandlerThread:24736 [handler.py:handle_request():158] handle_request: status
2024-06-25 22:02:41,190 INFO    WriterThread:24736 [datastore.py:open_for_write():87] open: C:\Users\Bobby\Akash_Django\R\Droupout2 (another copy)\PFLlib\system\wandb\run-20240625_220241-y0yab5gu\run-y0yab5gu.wandb
2024-06-25 22:02:41,190 DEBUG   SenderThread:24736 [sender.py:send():378] send: header
2024-06-25 22:02:41,332 DEBUG   SenderThread:24736 [sender.py:send():378] send: run
2024-06-25 22:02:42,233 ERROR   SenderThread:24736 [internal_api.py:execute():344] 400 response executing GraphQL.
2024-06-25 22:02:42,233 ERROR   SenderThread:24736 [internal_api.py:execute():345] {"errors":[{"message":"you may not log runs directly to your organization, please try using your team entity","path":["upsertBucket"]}],"data":{"upsertBucket":null}}
2024-06-25 22:02:42,233 ERROR   SenderThread:24736 [sender.py:send_run():970] you may not log runs directly to your organization, please try using your team entity (Error 400: Bad Request)
Traceback (most recent call last):
  File "C:\Users\Bobby\AppData\Local\Programs\Python\Python312\Lib\site-packages\wandb\apis\normalize.py", line 41, in wrapper
    return func(*args, **kwargs)
           ^^^^^^^^^^^^^^^^^^^^^
  File "C:\Users\Bobby\AppData\Local\Programs\Python\Python312\Lib\site-packages\wandb\sdk\internal\internal_api.py", line 2188, in upsert_run
    response = self.gql(
               ^^^^^^^^^
  File "C:\Users\Bobby\AppData\Local\Programs\Python\Python312\Lib\site-packages\wandb\sdk\internal\internal_api.py", line 312, in gql
    ret = self._retry_gql(
          ^^^^^^^^^^^^^^^^
  File "C:\Users\Bobby\AppData\Local\Programs\Python\Python312\Lib\site-packages\wandb\sdk\lib\retry.py", line 131, in __call__
    result = self._call_fn(*args, **kwargs)
             ^^^^^^^^^^^^^^^^^^^^^^^^^^^^^^
  File "C:\Users\Bobby\AppData\Local\Programs\Python\Python312\Lib\site-packages\wandb\sdk\internal\internal_api.py", line 340, in execute
    return self.client.execute(*args, **kwargs)  # type: ignore
           ^^^^^^^^^^^^^^^^^^^^^^^^^^^^^^^^^^^^
  File "C:\Users\Bobby\AppData\Local\Programs\Python\Python312\Lib\site-packages\wandb\vendor\gql-0.2.0\wandb_gql\client.py", line 52, in execute
    result = self._get_result(document, *args, **kwargs)
             ^^^^^^^^^^^^^^^^^^^^^^^^^^^^^^^^^^^^^^^^^^^
  File "C:\Users\Bobby\AppData\Local\Programs\Python\Python312\Lib\site-packages\wandb\vendor\gql-0.2.0\wandb_gql\client.py", line 60, in _get_result
    return self.transport.execute(document, *args, **kwargs)
           ^^^^^^^^^^^^^^^^^^^^^^^^^^^^^^^^^^^^^^^^^^^^^^^^^
  File "C:\Users\Bobby\AppData\Local\Programs\Python\Python312\Lib\site-packages\wandb\sdk\lib\gql_request.py", line 59, in execute
    request.raise_for_status()
  File "C:\Users\Bobby\AppData\Local\Programs\Python\Python312\Lib\site-packages\requests\models.py", line 1024, in raise_for_status
    raise HTTPError(http_error_msg, response=self)
requests.exceptions.HTTPError: 400 Client Error: Bad Request for url: https://api.wandb.ai/graphql

During handling of the above exception, another exception occurred:

Traceback (most recent call last):
  File "C:\Users\Bobby\AppData\Local\Programs\Python\Python312\Lib\site-packages\wandb\sdk\internal\sender.py", line 968, in send_run
    server_run = self._init_run(run, config_value_dict)
                 ^^^^^^^^^^^^^^^^^^^^^^^^^^^^^^^^^^^^^^
  File "C:\Users\Bobby\AppData\Local\Programs\Python\Python312\Lib\site-packages\wandb\sdk\internal\sender.py", line 1013, in _init_run
    server_run, inserted, server_messages = self._api.upsert_run(
                                            ^^^^^^^^^^^^^^^^^^^^^
  File "C:\Users\Bobby\AppData\Local\Programs\Python\Python312\Lib\site-packages\wandb\apis\normalize.py", line 51, in wrapper
    raise CommError(message, error)
wandb.errors.CommError: you may not log runs directly to your organization, please try using your team entity (Error 400: Bad Request)
2024-06-25 22:02:42,975 DEBUG   HandlerThread:24736 [handler.py:handle_request():158] handle_request: shutdown
2024-06-25 22:02:42,975 INFO    HandlerThread:24736 [handler.py:finish():882] shutting down handler
2024-06-25 22:02:43,261 INFO    SenderThread:24736 [sender.py:finish():1545] shutting down sender
2024-06-25 22:02:43,371 INFO    WriterThread:24736 [datastore.py:close():296] close: C:\Users\Bobby\Akash_Django\R\Droupout2 (another copy)\PFLlib\system\wandb\run-20240625_220241-y0yab5gu\run-y0yab5gu.wandb
