2024-06-30 18:15:55,648 INFO    StreamThr :14272 [internal.py:wandb_internal():85] W&B internal server running at pid: 14272, started at: 2024-06-30 18:15:55.648345
2024-06-30 18:15:55,648 DEBUG   HandlerThread:14272 [handler.py:handle_request():158] handle_request: status
2024-06-30 18:15:55,672 INFO    WriterThread:14272 [datastore.py:open_for_write():87] open: C:\Users\Bobby\Akash_Django\R\fl\PFLlib\system\wandb\run-20240630_181555-8equfswi\run-8equfswi.wandb
2024-06-30 18:15:55,672 DEBUG   SenderThread:14272 [sender.py:send():378] send: header
2024-06-30 18:15:55,785 DEBUG   SenderThread:14272 [sender.py:send():378] send: run
2024-06-30 18:15:56,648 ERROR   SenderThread:14272 [internal_api.py:execute():344] 404 response executing GraphQL.
2024-06-30 18:15:56,648 ERROR   SenderThread:14272 [internal_api.py:execute():345] {"errors":[{"message":"project not found","path":["upsertBucket"]}],"data":{"upsertBucket":null}}
2024-06-30 18:15:56,669 ERROR   SenderThread:14272 [sender.py:send_run():970] It appears that you do not have permission to access the requested resource. Please reach out to the project owner to grant you access. If you have the correct permissions, verify that there are no issues with your networking setup.(Error 404: Not Found)
Traceback (most recent call last):
  File "C:\Users\Bobby\AppData\Local\Programs\Python\Python312\Lib\site-packages\wandb\sdk\lib\retry.py", line 131, in __call__
    result = self._call_fn(*args, **kwargs)
             ^^^^^^^^^^^^^^^^^^^^^^^^^^^^^^
  File "C:\Users\Bobby\AppData\Local\Programs\Python\Python312\Lib\site-packages\wandb\sdk\internal\internal_api.py", line 340, in execute
    return self.client.execute(*args, **kwargs)  # type: ignore
           ^^^^^^^^^^^^^^^^^^^^^^^^^^^^^^^^^^^^
  File "C:\Users\Bobby\AppData\Local\Programs\Python\Python312\Lib\site-packages\wandb\vendor\gql-0.2.0\wandb_gql\client.py", line 52, in execute
    result = self._get_result(document, *args, **kwargs)
             ^^^^^^^^^^^^^^^^^^^^^^^^^^^^^^^^^^^^^^^^^^^
  File "C:\Users\Bobby\AppData\Local\Programs\Python\Python312\Lib\site-packages\wandb\vendor\gql-0.2.0\wandb_gql\client.py", line 60, in _get_result
    return self.transport.execute(document, *args, **kwargs)
           ^^^^^^^^^^^^^^^^^^^^^^^^^^^^^^^^^^^^^^^^^^^^^^^^^
  File "C:\Users\Bobby\AppData\Local\Programs\Python\Python312\Lib\site-packages\wandb\sdk\lib\gql_request.py", line 59, in execute
    request.raise_for_status()
  File "C:\Users\Bobby\AppData\Local\Programs\Python\Python312\Lib\site-packages\requests\models.py", line 1024, in raise_for_status
    raise HTTPError(http_error_msg, response=self)
requests.exceptions.HTTPError: 404 Client Error: Not Found for url: https://api.wandb.ai/graphql

During handling of the above exception, another exception occurred:

Traceback (most recent call last):
  File "C:\Users\Bobby\AppData\Local\Programs\Python\Python312\Lib\site-packages\wandb\sdk\internal\sender.py", line 968, in send_run
    server_run = self._init_run(run, config_value_dict)
                 ^^^^^^^^^^^^^^^^^^^^^^^^^^^^^^^^^^^^^^
  File "C:\Users\Bobby\AppData\Local\Programs\Python\Python312\Lib\site-packages\wandb\sdk\internal\sender.py", line 1013, in _init_run
    server_run, inserted, server_messages = self._api.upsert_run(
                                            ^^^^^^^^^^^^^^^^^^^^^
  File "C:\Users\Bobby\AppData\Local\Programs\Python\Python312\Lib\site-packages\wandb\apis\normalize.py", line 73, in wrapper
    raise err
  File "C:\Users\Bobby\AppData\Local\Programs\Python\Python312\Lib\site-packages\wandb\apis\normalize.py", line 41, in wrapper
    return func(*args, **kwargs)
           ^^^^^^^^^^^^^^^^^^^^^
  File "C:\Users\Bobby\AppData\Local\Programs\Python\Python312\Lib\site-packages\wandb\sdk\internal\internal_api.py", line 2188, in upsert_run
    response = self.gql(
               ^^^^^^^^^
  File "C:\Users\Bobby\AppData\Local\Programs\Python\Python312\Lib\site-packages\wandb\sdk\internal\internal_api.py", line 312, in gql
    ret = self._retry_gql(
          ^^^^^^^^^^^^^^^^
  File "C:\Users\Bobby\AppData\Local\Programs\Python\Python312\Lib\site-packages\wandb\sdk\lib\retry.py", line 147, in __call__
    retry_timedelta_triggered = check_retry_fn(e)
                                ^^^^^^^^^^^^^^^^^
  File "C:\Users\Bobby\AppData\Local\Programs\Python\Python312\Lib\site-packages\wandb\util.py", line 965, in check_retry_fn
    return fallback_retry_fn(e)
           ^^^^^^^^^^^^^^^^^^^^
  File "C:\Users\Bobby\AppData\Local\Programs\Python\Python312\Lib\site-packages\wandb\util.py", line 907, in no_retry_auth
    raise CommError(
wandb.errors.CommError: It appears that you do not have permission to access the requested resource. Please reach out to the project owner to grant you access. If you have the correct permissions, verify that there are no issues with your networking setup.(Error 404: Not Found)
2024-06-30 18:15:58,229 DEBUG   HandlerThread:14272 [handler.py:handle_request():158] handle_request: shutdown
2024-06-30 18:15:58,229 INFO    HandlerThread:14272 [handler.py:finish():882] shutting down handler
2024-06-30 18:15:58,815 INFO    WriterThread:14272 [datastore.py:close():296] close: C:\Users\Bobby\Akash_Django\R\fl\PFLlib\system\wandb\run-20240630_181555-8equfswi\run-8equfswi.wandb
2024-06-30 18:15:59,065 INFO    SenderThread:14272 [sender.py:finish():1545] shutting down sender
