2024-06-29 10:25:45,887 INFO    StreamThr :47078 [internal.py:wandb_internal():85] W&B internal server running at pid: 47078, started at: 2024-06-29 10:25:45.887298
2024-06-29 10:25:45,889 DEBUG   HandlerThread:47078 [handler.py:handle_request():158] handle_request: status
2024-06-29 10:25:45,894 INFO    WriterThread:47078 [datastore.py:open_for_write():87] open: /home/student/R/fl/PFLlib/system/wandb/run-20240629_102545-po2p9v7u/run-po2p9v7u.wandb
2024-06-29 10:25:45,894 DEBUG   SenderThread:47078 [sender.py:send():379] send: header
2024-06-29 10:25:45,910 DEBUG   SenderThread:47078 [sender.py:send():379] send: run
2024-06-29 10:25:46,514 ERROR   SenderThread:47078 [internal_api.py:execute():344] 403 response executing GraphQL.
2024-06-29 10:25:46,514 ERROR   SenderThread:47078 [internal_api.py:execute():345] {"errors":[{"message":"permission denied","path":["upsertBucket"],"extensions":{"code":"PERMISSION_ERROR"}}],"data":{"upsertBucket":null}}
2024-06-29 10:25:46,514 ERROR   SenderThread:47078 [sender.py:send_run():1009] It appears that you do not have permission to access the requested resource. Please reach out to the project owner to grant you access. If you have the correct permissions, verify that there are no issues with your networking setup.(Error 403: Forbidden)
Traceback (most recent call last):
  File "/home/student/.local/lib/python3.9/site-packages/wandb/sdk/lib/retry.py", line 131, in __call__
    result = self._call_fn(*args, **kwargs)
  File "/home/student/.local/lib/python3.9/site-packages/wandb/sdk/internal/internal_api.py", line 340, in execute
    return self.client.execute(*args, **kwargs)  # type: ignore
  File "/home/student/.local/lib/python3.9/site-packages/wandb/vendor/gql-0.2.0/wandb_gql/client.py", line 52, in execute
    result = self._get_result(document, *args, **kwargs)
  File "/home/student/.local/lib/python3.9/site-packages/wandb/vendor/gql-0.2.0/wandb_gql/client.py", line 60, in _get_result
    return self.transport.execute(document, *args, **kwargs)
  File "/home/student/.local/lib/python3.9/site-packages/wandb/sdk/lib/gql_request.py", line 59, in execute
    request.raise_for_status()
  File "/home/student/.local/lib/python3.9/site-packages/requests/models.py", line 1024, in raise_for_status
    raise HTTPError(http_error_msg, response=self)
requests.exceptions.HTTPError: 403 Client Error: Forbidden for url: https://api.wandb.ai/graphql

During handling of the above exception, another exception occurred:

Traceback (most recent call last):
  File "/home/student/.local/lib/python3.9/site-packages/wandb/sdk/internal/sender.py", line 1007, in send_run
    server_run = self._init_run(run, config_value_dict)
  File "/home/student/.local/lib/python3.9/site-packages/wandb/sdk/internal/sender.py", line 1079, in _init_run
    server_run, inserted, server_messages = self._api.upsert_run(
  File "/home/student/.local/lib/python3.9/site-packages/wandb/apis/normalize.py", line 73, in wrapper
    raise err
  File "/home/student/.local/lib/python3.9/site-packages/wandb/apis/normalize.py", line 41, in wrapper
    return func(*args, **kwargs)
  File "/home/student/.local/lib/python3.9/site-packages/wandb/sdk/internal/internal_api.py", line 2190, in upsert_run
    response = self.gql(
  File "/home/student/.local/lib/python3.9/site-packages/wandb/sdk/internal/internal_api.py", line 312, in gql
    ret = self._retry_gql(
  File "/home/student/.local/lib/python3.9/site-packages/wandb/sdk/lib/retry.py", line 147, in __call__
    retry_timedelta_triggered = check_retry_fn(e)
  File "/home/student/.local/lib/python3.9/site-packages/wandb/util.py", line 968, in check_retry_fn
    return fallback_retry_fn(e)
  File "/home/student/.local/lib/python3.9/site-packages/wandb/util.py", line 910, in no_retry_auth
    raise CommError(
wandb.errors.CommError: It appears that you do not have permission to access the requested resource. Please reach out to the project owner to grant you access. If you have the correct permissions, verify that there are no issues with your networking setup.(Error 403: Forbidden)
2024-06-29 10:25:46,712 DEBUG   HandlerThread:47078 [handler.py:handle_request():158] handle_request: shutdown
2024-06-29 10:25:46,712 INFO    HandlerThread:47078 [handler.py:finish():882] shutting down handler
2024-06-29 10:25:46,911 INFO    WriterThread:47078 [datastore.py:close():296] close: /home/student/R/fl/PFLlib/system/wandb/run-20240629_102545-po2p9v7u/run-po2p9v7u.wandb
2024-06-29 10:25:47,517 INFO    SenderThread:47078 [sender.py:finish():1608] shutting down sender
